2023-06-06 18:14:53,597 INFO    MainThread:4740 [wandb_setup.py:_flush():76] Current SDK version is 0.15.3
2023-06-06 18:14:53,598 INFO    MainThread:4740 [wandb_setup.py:_flush():76] Configure stats pid to 4740
2023-06-06 18:14:53,598 INFO    MainThread:4740 [wandb_setup.py:_flush():76] Loading settings from C:\Users\Neko\.config\wandb\settings
2023-06-06 18:14:53,598 INFO    MainThread:4740 [wandb_setup.py:_flush():76] Loading settings from C:\Users\Neko\OneDrive\Desktop\learning\Homework\mlops_zoomcamp\experiment-tracking\wnb\wandb\settings
2023-06-06 18:14:53,598 INFO    MainThread:4740 [wandb_setup.py:_flush():76] Loading settings from environment variables: {}
2023-06-06 18:14:53,598 INFO    MainThread:4740 [wandb_setup.py:_flush():76] Applying setup settings: {'_disable_service': False}
2023-06-06 18:14:53,599 INFO    MainThread:4740 [wandb_setup.py:_flush():76] Inferring run settings from compute environment: {'program_relpath': 'experiment-tracking\\wnb\\preprocess_data.py', 'program': 'C:\\Users\\Neko\\OneDrive\\Desktop\\learning\\Homework\\mlops_zoomcamp\\experiment-tracking\\wnb\\preprocess_data.py'}
2023-06-06 18:14:53,599 INFO    MainThread:4740 [wandb_init.py:_log_setup():507] Logging user logs to C:\Users\Neko\OneDrive\Desktop\learning\Homework\mlops_zoomcamp\experiment-tracking\wnb\wandb\run-20230606_181453-rdgq4jdo\logs\debug.log
2023-06-06 18:14:53,599 INFO    MainThread:4740 [wandb_init.py:_log_setup():508] Logging internal logs to C:\Users\Neko\OneDrive\Desktop\learning\Homework\mlops_zoomcamp\experiment-tracking\wnb\wandb\run-20230606_181453-rdgq4jdo\logs\debug-internal.log
2023-06-06 18:14:53,600 INFO    MainThread:4740 [wandb_init.py:init():547] calling init triggers
2023-06-06 18:14:53,600 INFO    MainThread:4740 [wandb_init.py:init():554] wandb.init called with sweep_config: {}
config: {}
2023-06-06 18:14:53,600 INFO    MainThread:4740 [wandb_init.py:init():596] starting backend
2023-06-06 18:14:53,600 INFO    MainThread:4740 [wandb_init.py:init():600] setting up manager
2023-06-06 18:14:53,604 INFO    MainThread:4740 [backend.py:_multiprocessing_setup():106] multiprocessing start_methods=spawn, using: spawn
2023-06-06 18:14:53,612 INFO    MainThread:4740 [wandb_init.py:init():606] backend started and connected
2023-06-06 18:14:53,616 INFO    MainThread:4740 [wandb_init.py:init():700] updated telemetry
2023-06-06 18:14:53,736 INFO    MainThread:4740 [wandb_init.py:init():737] communicating run to backend with 60.0 second timeout
2023-06-06 18:15:04,534 INFO    Thread-7  :4740 [retry.py:__call__():172] Retry attempt failed:
Traceback (most recent call last):
  File "C:\Users\Neko\OneDrive\Desktop\learning\Homework\mlops_zoomcamp\venv\lib\site-packages\urllib3\connection.py", line 174, in _new_conn
    conn = connection.create_connection(
  File "C:\Users\Neko\OneDrive\Desktop\learning\Homework\mlops_zoomcamp\venv\lib\site-packages\urllib3\util\connection.py", line 95, in create_connection
    raise err
  File "C:\Users\Neko\OneDrive\Desktop\learning\Homework\mlops_zoomcamp\venv\lib\site-packages\urllib3\util\connection.py", line 85, in create_connection
    sock.connect(sa)
ConnectionRefusedError: [WinError 10061] No connection could be made because the target machine actively refused it

During handling of the above exception, another exception occurred:

Traceback (most recent call last):
  File "C:\Users\Neko\OneDrive\Desktop\learning\Homework\mlops_zoomcamp\venv\lib\site-packages\urllib3\connectionpool.py", line 714, in urlopen
    httplib_response = self._make_request(
  File "C:\Users\Neko\OneDrive\Desktop\learning\Homework\mlops_zoomcamp\venv\lib\site-packages\urllib3\connectionpool.py", line 415, in _make_request
    conn.request(method, url, **httplib_request_kw)
  File "C:\Users\Neko\OneDrive\Desktop\learning\Homework\mlops_zoomcamp\venv\lib\site-packages\urllib3\connection.py", line 244, in request
    super(HTTPConnection, self).request(method, url, body=body, headers=headers)
  File "C:\Users\Neko\AppData\Local\Programs\Python\Python39\lib\http\client.py", line 1255, in request
    self._send_request(method, url, body, headers, encode_chunked)
  File "C:\Users\Neko\AppData\Local\Programs\Python\Python39\lib\http\client.py", line 1301, in _send_request
    self.endheaders(body, encode_chunked=encode_chunked)
  File "C:\Users\Neko\AppData\Local\Programs\Python\Python39\lib\http\client.py", line 1250, in endheaders
    self._send_output(message_body, encode_chunked=encode_chunked)
  File "C:\Users\Neko\AppData\Local\Programs\Python\Python39\lib\http\client.py", line 1010, in _send_output
    self.send(msg)
  File "C:\Users\Neko\AppData\Local\Programs\Python\Python39\lib\http\client.py", line 950, in send
    self.connect()
  File "C:\Users\Neko\OneDrive\Desktop\learning\Homework\mlops_zoomcamp\venv\lib\site-packages\urllib3\connection.py", line 205, in connect
    conn = self._new_conn()
  File "C:\Users\Neko\OneDrive\Desktop\learning\Homework\mlops_zoomcamp\venv\lib\site-packages\urllib3\connection.py", line 186, in _new_conn
    raise NewConnectionError(
urllib3.exceptions.NewConnectionError: <urllib3.connection.HTTPConnection object at 0x000001C5FC7546A0>: Failed to establish a new connection: [WinError 10061] No connection could be made because the target machine actively refused it

During handling of the above exception, another exception occurred:

Traceback (most recent call last):
  File "C:\Users\Neko\OneDrive\Desktop\learning\Homework\mlops_zoomcamp\venv\lib\site-packages\requests\adapters.py", line 486, in send
    resp = conn.urlopen(
  File "C:\Users\Neko\OneDrive\Desktop\learning\Homework\mlops_zoomcamp\venv\lib\site-packages\urllib3\connectionpool.py", line 798, in urlopen
    retries = retries.increment(
  File "C:\Users\Neko\OneDrive\Desktop\learning\Homework\mlops_zoomcamp\venv\lib\site-packages\urllib3\util\retry.py", line 592, in increment
    raise MaxRetryError(_pool, url, error or ResponseError(cause))
urllib3.exceptions.MaxRetryError: HTTPConnectionPool(host='localhost', port=8080): Max retries exceeded with url: /graphql (Caused by NewConnectionError('<urllib3.connection.HTTPConnection object at 0x000001C5FC7546A0>: Failed to establish a new connection: [WinError 10061] No connection could be made because the target machine actively refused it'))

During handling of the above exception, another exception occurred:

Traceback (most recent call last):
  File "C:\Users\Neko\OneDrive\Desktop\learning\Homework\mlops_zoomcamp\venv\lib\site-packages\wandb\sdk\lib\retry.py", line 131, in __call__
    result = self._call_fn(*args, **kwargs)
  File "C:\Users\Neko\OneDrive\Desktop\learning\Homework\mlops_zoomcamp\venv\lib\site-packages\wandb\sdk\internal\internal_api.py", line 285, in execute
    return self.client.execute(*args, **kwargs)  # type: ignore
  File "C:\Users\Neko\OneDrive\Desktop\learning\Homework\mlops_zoomcamp\venv\lib\site-packages\wandb\vendor\gql-0.2.0\wandb_gql\client.py", line 52, in execute
    result = self._get_result(document, *args, **kwargs)
  File "C:\Users\Neko\OneDrive\Desktop\learning\Homework\mlops_zoomcamp\venv\lib\site-packages\wandb\vendor\gql-0.2.0\wandb_gql\client.py", line 60, in _get_result
    return self.transport.execute(document, *args, **kwargs)
  File "C:\Users\Neko\OneDrive\Desktop\learning\Homework\mlops_zoomcamp\venv\lib\site-packages\wandb\sdk\lib\gql_request.py", line 55, in execute
    request = self.session.post(self.url, **post_args)
  File "C:\Users\Neko\OneDrive\Desktop\learning\Homework\mlops_zoomcamp\venv\lib\site-packages\requests\sessions.py", line 637, in post
    return self.request("POST", url, data=data, json=json, **kwargs)
  File "C:\Users\Neko\OneDrive\Desktop\learning\Homework\mlops_zoomcamp\venv\lib\site-packages\requests\sessions.py", line 589, in request
    resp = self.send(prep, **send_kwargs)
  File "C:\Users\Neko\OneDrive\Desktop\learning\Homework\mlops_zoomcamp\venv\lib\site-packages\requests\sessions.py", line 703, in send
    r = adapter.send(request, **kwargs)
  File "C:\Users\Neko\OneDrive\Desktop\learning\Homework\mlops_zoomcamp\venv\lib\site-packages\requests\adapters.py", line 519, in send
    raise ConnectionError(e, request=request)
requests.exceptions.ConnectionError: HTTPConnectionPool(host='localhost', port=8080): Max retries exceeded with url: /graphql (Caused by NewConnectionError('<urllib3.connection.HTTPConnection object at 0x000001C5FC7546A0>: Failed to establish a new connection: [WinError 10061] No connection could be made because the target machine actively refused it'))
2023-06-06 18:15:54,281 ERROR   MainThread:4740 [wandb_init.py:init():763] encountered error: Run initialization has timed out after 60.0 sec. 
Please refer to the documentation for additional information: https://docs.wandb.ai/guides/track/tracking-faq#initstarterror-error-communicating-with-wandb-process-
2023-06-06 18:15:54,512 ERROR   MainThread:4740 [wandb_init.py:init():1168] Run initialization has timed out after 60.0 sec. 
Please refer to the documentation for additional information: https://docs.wandb.ai/guides/track/tracking-faq#initstarterror-error-communicating-with-wandb-process-
Traceback (most recent call last):
  File "C:\Users\Neko\OneDrive\Desktop\learning\Homework\mlops_zoomcamp\venv\lib\site-packages\wandb\sdk\wandb_init.py", line 1150, in init
    run = wi.init()
  File "C:\Users\Neko\OneDrive\Desktop\learning\Homework\mlops_zoomcamp\venv\lib\site-packages\wandb\sdk\wandb_init.py", line 769, in init
    raise error
wandb.errors.CommError: Run initialization has timed out after 60.0 sec. 
Please refer to the documentation for additional information: https://docs.wandb.ai/guides/track/tracking-faq#initstarterror-error-communicating-with-wandb-process-
2023-06-06 18:15:55,534 WARNING MsgRouterThr:4740 [router.py:message_loop():77] message_loop has been closed
