2023-06-06 18:20:38,101 INFO    StreamThr :11164 [internal.py:wandb_internal():86] W&B internal server running at pid: 11164, started at: 2023-06-06 18:20:38.101175
2023-06-06 18:20:38,102 DEBUG   HandlerThread:11164 [handler.py:handle_request():144] handle_request: status
2023-06-06 18:20:38,108 INFO    WriterThread:11164 [datastore.py:open_for_write():85] open: C:\Users\Neko\OneDrive\Desktop\learning\Homework\mlops_zoomcamp\experiment-tracking\wnb\wandb\run-20230606_182038-2r8yimga\run-2r8yimga.wandb
2023-06-06 18:20:38,109 DEBUG   SenderThread:11164 [sender.py:send():375] send: header
2023-06-06 18:20:38,156 DEBUG   SenderThread:11164 [sender.py:send():375] send: run
2023-06-06 18:20:38,217 ERROR   SenderThread:11164 [internal_api.py:execute():288] 401 response executing GraphQL.
2023-06-06 18:20:38,219 ERROR   SenderThread:11164 [internal_api.py:execute():289] {"errors":[{"message":"user is not logged in","path":["upsertBucket"],"extensions":{"code":"PERMISSION_ERROR"}}],"data":{"upsertBucket":null}}
2023-06-06 18:20:38,224 ERROR   SenderThread:11164 [sender.py:send_run():979] The API key you provided is either invalid or missing.  If the `WANDB_API_KEY` environment variable is set, make sure it is correct. Otherwise, to resolve this issue, you may try running the 'wandb login --relogin' command. If you are using a local server, make sure that you're using the correct hostname. If you're not sure, you can try logging in again using the 'wandb login --relogin --host [hostname]' command.(Error 401: Unauthorized)
Traceback (most recent call last):
  File "C:\Users\Neko\OneDrive\Desktop\learning\Homework\mlops_zoomcamp\venv\lib\site-packages\wandb\sdk\lib\retry.py", line 131, in __call__
    result = self._call_fn(*args, **kwargs)
  File "C:\Users\Neko\OneDrive\Desktop\learning\Homework\mlops_zoomcamp\venv\lib\site-packages\wandb\sdk\internal\internal_api.py", line 285, in execute
    return self.client.execute(*args, **kwargs)  # type: ignore
  File "C:\Users\Neko\OneDrive\Desktop\learning\Homework\mlops_zoomcamp\venv\lib\site-packages\wandb\vendor\gql-0.2.0\wandb_gql\client.py", line 52, in execute
    result = self._get_result(document, *args, **kwargs)
  File "C:\Users\Neko\OneDrive\Desktop\learning\Homework\mlops_zoomcamp\venv\lib\site-packages\wandb\vendor\gql-0.2.0\wandb_gql\client.py", line 60, in _get_result
    return self.transport.execute(document, *args, **kwargs)
  File "C:\Users\Neko\OneDrive\Desktop\learning\Homework\mlops_zoomcamp\venv\lib\site-packages\wandb\sdk\lib\gql_request.py", line 56, in execute
    request.raise_for_status()
  File "C:\Users\Neko\OneDrive\Desktop\learning\Homework\mlops_zoomcamp\venv\lib\site-packages\requests\models.py", line 1021, in raise_for_status
    raise HTTPError(http_error_msg, response=self)
requests.exceptions.HTTPError: 401 Client Error: Unauthorized for url: http://localhost:8080/graphql

During handling of the above exception, another exception occurred:

Traceback (most recent call last):
  File "C:\Users\Neko\OneDrive\Desktop\learning\Homework\mlops_zoomcamp\venv\lib\site-packages\wandb\sdk\internal\sender.py", line 977, in send_run
    self._init_run(run, config_value_dict)
  File "C:\Users\Neko\OneDrive\Desktop\learning\Homework\mlops_zoomcamp\venv\lib\site-packages\wandb\sdk\internal\sender.py", line 1015, in _init_run
    server_run, inserted, server_messages = self._api.upsert_run(
  File "C:\Users\Neko\OneDrive\Desktop\learning\Homework\mlops_zoomcamp\venv\lib\site-packages\wandb\apis\normalize.py", line 73, in wrapper
    raise err
  File "C:\Users\Neko\OneDrive\Desktop\learning\Homework\mlops_zoomcamp\venv\lib\site-packages\wandb\apis\normalize.py", line 41, in wrapper
    return func(*args, **kwargs)
  File "C:\Users\Neko\OneDrive\Desktop\learning\Homework\mlops_zoomcamp\venv\lib\site-packages\wandb\sdk\internal\internal_api.py", line 1690, in upsert_run
    response = self.gql(
  File "C:\Users\Neko\OneDrive\Desktop\learning\Homework\mlops_zoomcamp\venv\lib\site-packages\wandb\sdk\internal\internal_api.py", line 257, in gql
    ret = self._retry_gql(
  File "C:\Users\Neko\OneDrive\Desktop\learning\Homework\mlops_zoomcamp\venv\lib\site-packages\wandb\sdk\lib\retry.py", line 147, in __call__
    retry_timedelta_triggered = check_retry_fn(e)
  File "C:\Users\Neko\OneDrive\Desktop\learning\Homework\mlops_zoomcamp\venv\lib\site-packages\wandb\util.py", line 907, in check_retry_fn
    return fallback_retry_fn(e)
  File "C:\Users\Neko\OneDrive\Desktop\learning\Homework\mlops_zoomcamp\venv\lib\site-packages\wandb\util.py", line 838, in no_retry_auth
    raise AuthenticationError(
wandb.errors.AuthenticationError: The API key you provided is either invalid or missing.  If the `WANDB_API_KEY` environment variable is set, make sure it is correct. Otherwise, to resolve this issue, you may try running the 'wandb login --relogin' command. If you are using a local server, make sure that you're using the correct hostname. If you're not sure, you can try logging in again using the 'wandb login --relogin --host [hostname]' command.(Error 401: Unauthorized)
2023-06-06 18:20:38,458 DEBUG   HandlerThread:11164 [handler.py:handle_request():144] handle_request: shutdown
2023-06-06 18:20:38,458 INFO    HandlerThread:11164 [handler.py:finish():842] shutting down handler
2023-06-06 18:20:39,158 INFO    WriterThread:11164 [datastore.py:close():298] close: C:\Users\Neko\OneDrive\Desktop\learning\Homework\mlops_zoomcamp\experiment-tracking\wnb\wandb\run-20230606_182038-2r8yimga\run-2r8yimga.wandb
2023-06-06 18:20:39,237 INFO    SenderThread:11164 [sender.py:finish():1550] shutting down sender
